Workbook

Sheet Read Me
A1: Conclusion Score — every calculation, live
A3: This workbook is a working model of the original Idea Stock Exchange scoring process — the
A4: one from 'Conclusions about the Church with arguments in separate columns'. Every conclusion
A5: lists reasons to agree and reasons to disagree; every listed reason is worth one point to its
A6: column; a reason with its own page adds its own score, weighted by the edge's linkage score
A7: and the sub-argument multiplier m:
A9: score = (nAgree - nDisagree) + m x ( sum agree childScore x LS - sum disagree childScore x LS )
A10: LS = (linkAgree - linkDisagree) / (linkAgree + linkDisagree), 1 when undebated
A12: Sheets:
A13: Scoreboard every conclusion ranked by its live score (the old Index sheet)
A14: Walkthrough one score derived step by step, with a linkage mini-calculator
A15: Nodes one row per conclusion: counts, sums, and the score formula
... A39: examples/php-score-retrieval/ runnable PHP + SQLite demo pages

Sheet Settings
A1: Settings
A3: Sub-argument multiplier (m) | B3: 0.7 | C3: EDIT ME. The workbook's Index!O1 cell. 0.7 = the documented intent (each level of sub-arguments counts 70% as much). Set to 1.0 to reproduce the original workbook's live sheets exactly (46 scores 16, 47 scores 8, 45 scores 6).
A5: Undebated linkage default | B5: 1 | C5: Informational: an edge with no linkage votes uses LS = 1 (the Edges sheet formula applies this; changing this cell has no effect). A reason is assumed on-topic until someone debates the linkage.

Sheet Nodes
A1: Nodes — one row per conclusion (the workbook's numbered sheets)
A2: Nothing to edit here: counts and sums aggregate the Edges sheet; the score is raw + m x (sum agree - sum disagree). Add rows on Edges and these update.
A4: ID | B4: Conclusion | C4: Set | D4: # agree | E4: # disagree | F4: Sum agree contrib | G4: Sum disagree contrib | H4: Score | I4: Rank in set
A5: 46 | B5: Mormons should not be afraid of investigating the truth about their religion. | C5: church | D5: =COUNTIF(Edges!$D$5:$D$8,"agree") -> 4 | E5: =COUNTIF(Edges!$D$5:$D$8,"disagree") -> 0 | F5: =SUMIF(Edges!$D$5:$D$8,"agree",Edges!$K$5:$K$8) -> 9.57 | G5: =SUMIF(Edges!$D$5:$D$8,"disagree",Edges!$K$5:$K$8) -> 0 | H5: =D5-E5+Settings!$B$3*(F5-G5) -> 10.699 | I5: =1+COUNTIFS($C$5:$C$120,$C5,$H$5:$H$120,">"&$H5) -> 1
A6: 47 | B6: Many LDS church leaders have encouraged the complete and utter loyalty to the Truth. | C6: church | D6: =COUNTIF(Edges!$D$9:$D$10,"agree") -> 2 | E6: =COUNTIF(Edges!$D$9:$D$10,"disagree") -> 0 | F6: =SUMIF(Edges!$D$9:$D$10,"agree",Edges!$K$9:$K$10) -> 5.1 | G6: =SUMIF(Edges!$D$9:$D$10,"disagree",Edges!$K$9:$K$10) -> 0 | H6: =D6-E6+Settings!$B$3*(F6-G6) -> 5.57 | I6: =1+COUNTIFS($C$5:$C$120,$C6,$H$5:$H$120,">"&$H6) -> 2
A7: 45 | B7: President J. Reuben Clark was right: if we have the truth, it cannot be harmed by investigation. | C7: church | D7: =COUNTIF(Edges!$D$15:$D$19,"agree") -> 4 | E7: =COUNTIF(Edges!$D$15:$D$19,"disagree") -> 1 | F7: =SUMIF(Edges!$D$15:$D$19,"agree",Edges!$K$15:$K$19) -> 3 | G7: =SUMIF(Edges!$D$15:$D$19,"disagree",Edges!$K$15:$K$19) -> 0 | H7: =D7-E7+Settings!$B$3*(F7-G7) -> 5.1 | I7: =1+COUNTIFS($C$5:$C$120,$C7,$H$5:$H$120,">"&$H7) -> 3
A8: 30 | B8: God is truth and knowledge; hiding truth to keep people in a religion is the opposite of God. | C8: church | D8: =COUNTIF(Edges!$D$20:$D$22,"agree") -> 2 | E8: =COUNTIF(Edges!$D$20:$D$22,"disagree") -> 1 | F8: =SUMIF(Edges!$D$20:$D$22,"agree",Edges!$K$20:$K$22) -> 0 | G8: =SUMIF(Edges!$D$20:$D$22,"disagree",Edges!$K$20:$K$22) -> 0 | H8: =D8-E8+Settings!$B$3*(F8-G8) -> 1 | I8: =1+COUNTIFS($C$5:$C$120,$C8,$H$5:$H$120,">"&$H8) -> 5
A9: 48 | B9: LDS doctrine teaches that you cannot be saved in ignorance. | C9: church | D9: =COUNTIF(Edges!$D$11:$D$12,"agree") -> 2 | E9: =COUNTIF(Edges!$D$11:$D$12,"disagree") -> 0 | F9: =SUMIF(Edges!$D$11:$D$12,"agree",Edges!$K$11:$K$12) -> 0 | G9: =SUMIF(Edges!$D$11:$D$12,"disagree",Edges!$K$11:$K$12) -> 0 | H9: =D9-E9+Settings!$B$3*(F9-G9) -> 2 | I9: =1+COUNTIFS($C$5:$C$120,$C9,$H$5:$H$120,">"&$H9) -> 4
A10: 296 | B10: If you cannot be saved in ignorance, you will eventually learn about all the Church's warts. | C10: church | D10: =COUNTIF(Edges!$D$13:$D$13,"agree") -> 1 | E10: =COUNTIF(Edges!$D$13:$D$13,"disagree") -> 0 | F10: =SUMIF(Edges!$D$13:$D$13,"agree",Edges!$K$13:$K$13) -> 0 | G10: =SUMIF(Edges!$D$13:$D$13,"disagree",Edges!$K$13:$K$13) -> 0 | H10: =D10-E10+Settings!$B$3*(F10-G10) -> 1 | I10: =1+COUNTIFS($C$5:$C$120,$C10,$H$5:$H$120,">"&$H10) -> 5
A11: 297 | B11: Even if the Mormon Church is true, its leaders should not use half truths to keep people in it. | C11: church | D11: =COUNTIF(Edges!$D$14:$D$14,"agree") -> 1 | E11: =COUNTIF(Edges!$D$14:$D$14,"disagree") -> 0 | F11: =SUMIF(Edges!$D$14:$D$14,"agree",Edges!$K$14:$K$14) -> 0 | G11: =SUMIF(Edges!$D$14:$D$14,"disagree",Edges!$K$14:$K$14) -> 0 | H11: =D11-E11+Settings!$B$3*(F11-G11) -> 1 | I11: =1+COUNTIFS($C$5:$C$120,$C11,$H$5:$H$120,">"&$H11) -> 5
A12: 301 | B12: The whole narrative of Joseph Smith starting the Church is that he asked of God (James 1:5). | C12: church | D12: 0 | E12: 0 | F12: 0 | G12: 0 | H12: =D12-E12+Settings!$B$3*(F12-G12) -> 0 | I12: =1+COUNTIFS($C$5:$C$120,$C12,$H$5:$H$120,">"&$H12) -> 8
A13: 302 | B13: D&C 131:6: It is impossible for a man to be saved in ignorance. | C13: church | D13: 0 | E13: 0 | F13: 0 | G13: 0 | H13: =D13-E13+Settings!$B$3*(F13-G13) -> 0 | I13: =1+COUNTIFS($C$5:$C$120,$C13,$H$5:$H$120,">"&$H13) -> 8
A14: 303 | B14: D&C 137:7: All who have died without a knowledge of this gospel... shall be heirs. | C14: church | D14: 0 | E14: 0 | F14: 0 | G14: 0 | H14: =D14-E14+Settings!$B$3*(F14-G14) -> 0 | I14: =1+COUNTIFS($C$5:$C$120,$C14,$H$5:$H$120,">"&$H14) -> 8
A15: 304 | B15: What information you expose yourself to determines what you learn eventually. | C15: church | D15: 0 | E15: 0 | F15: 0 | G15: 0 | H15: =D15-E15+Settings!$B$3*(F15-G15) -> 0 | I15: =1+COUNTIFS($C$5:$C$120,$C15,$H$5:$H$120,">"&$H15) -> 8
A16: 305 | B16: Telling half truths or hiding the whole truth serves an agenda other than truth. | C16: church | D16: 0 | E16: 0 | F16: 0 | G16: 0 | H16: =D16-E16+Settings!$B$3*(F16-G16) -> 0 | I16: =1+COUNTIFS($C$5:$C$120,$C16,$H$5:$H$120,">"&$H16) -> 8
A17: 306 | B17: Truth is always helped by honest, logical, transparent investigation. | C17: church | D17: 0 | E17: 0 | F17: 0 | G17: 0 | H17: =D17-E17+Settings!$B$3*(F17-G17) -> 0 | I17: =1+COUNTIFS($C$5:$C$120,$C17,$H$5:$H$120,">"&$H17) -> 8
A18: 307 | B18: Even if the Mormon Church is true, they shouldn't lie to keep people in it. | C18: church | D18: 0 | E18: 0 | F18: 0 | G18: 0 | H18: =D18-E18+Settings!$B$3*(F18-G18) -> 0 | I18: =1+COUNTIFS($C$5:$C$120,$C18,$H$5:$H$120,">"&$H18) -> 8
A19: 308 | B19: If God wants everyone to be Mormon, it is more important to tell faith-promoting stories. | C19: church | D19: 0 | E19: 0 | F19: 0 | G19: 0 | H19: =D19-E19+Settings!$B$3*(F19-G19) -> 0 | I19: =1+COUNTIFS($C$5:$C$120,$C19,$H$5:$H$120,">"&$H19) -> 8
A20: 309 | B20: The 10 commandments tell us not to bear false witness. | C20: church | D20: 0 | E20: 0 | F20: 0 | G20: 0 | H20: =D20-E20+Settings!$B$3*(F20-G20) -> 0 | I20: =1+COUNTIFS($C$5:$C$120,$C20,$H$5:$H$120,">"&$H20) -> 8
A21: 310 | B21: Mormons are told not to lie, or do anything like unto it. | C21: church | D21: 0 | E21: 0 | F21: 0 | G21: 0 | H21: =D21-E21+Settings!$B$3*(F21-G21) -> 0 | I21: =1+COUNTIFS($C$5:$C$120,$C21,$H$5:$H$120,">"&$H21) -> 8
A22: 311 | B22: Jesus said people should be given milk before meat. | C22: church | D22: 0 | E22: 0 | F22: 0 | G22: 0 | H22: =D22-E22+Settings!$B$3*(F22-G22) -> 0 | I22: =1+COUNTIFS($C$5:$C$120,$C22,$H$5:$H$120,">"&$H22) -> 8
A23: t1 | B23: Our city should plant more street trees. | C23: trees | D23: =COUNTIF(Edges!$D$23:$D$25,"agree") -> 2 | E23: =COUNTIF(Edges!$D$23:$D$25,"disagree") -> 1 | F23: =SUMIF(Edges!$D$23:$D$25,"agree",Edges!$K$23:$K$25) -> 2 | G23: =SUMIF(Edges!$D$23:$D$25,"disagree",Edges!$K$23:$K$25) -> 0.5 | H23: =D23-E23+Settings!$B$3*(F23-G23) -> 2.05 | I23: =1+COUNTIFS($C$5:$C$120,$C23,$H$5:$H$120,">"&$H23) -> 1
A24: t2 | B24: Street trees measurably cool neighborhoods in summer. | C24: trees | D24: =COUNTIF(Edges!$D$26:$D$27,"agree") -> 2 | E24: =COUNTIF(Edges!$D$26:$D$27,"disagree") -> 0 | F24: =SUMIF(Edges!$D$26:$D$27,"agree",Edges!$K$26:$K$27) -> 0 | G24: =SUMIF(Edges!$D$26:$D$27,"disagree",Edges!$K$26:$K$27) -> 0 | H24: =D24-E24+Settings!$B$3*(F24-G24) -> 2 | I24: =1+COUNTIFS($C$5:$C$120,$C24,$H$5:$H$120,">"&$H24) -> 2
A25: t3 | B25: Street trees increase nearby property values. | C25: trees | D25: =COUNTIF(Edges!$D$28:$D$29,"agree") -> 1 | E25: =COUNTIF(Edges!$D$28:$D$29,"disagree") -> 1 | F25: =SUMIF(Edges!$D$28:$D$29,"agree",Edges!$K$28:$K$29) -> 0 | G25: =SUMIF(Edges!$D$28:$D$29,"disagree",Edges!$K$28:$K$29) -> 0 | H25: =D25-E25+Settings!$B$3*(F25-G25) -> 0 | I25: =1+COUNTIFS($C$5:$C$120,$C25,$H$5:$H$120,">"&$H25) -> 4
A26: t4 | B26: Tree roots damage sidewalks and raise repair costs. | C26: trees | D26: =COUNTIF(Edges!$D$30:$D$30,"agree") -> 1 | E26: =COUNTIF(Edges!$D$30:$D$30,"disagree") -> 0 | F26: =SUMIF(Edges!$D$30:$D$30,"agree",Edges!$K$30:$K$30) -> 0 | G26: =SUMIF(Edges!$D$30:$D$30,"disagree",Edges!$K$30:$K$30) -> 0 | H26: =D26-E26+Settings!$B$3*(F26-G26) -> 1 | I26: =1+COUNTIFS($C$5:$C$120,$C26,$H$5:$H$120,">"&$H26) -> 3
A27: t5 | B27: Shaded pavement stays 10-15 degrees cooler in heat waves. | C27: trees | D27: 0 | E27: 0 | F27: 0 | G27: 0 | H27: =D27-E27+Settings!$B$3*(F27-G27) -> 0 | I27: =1+COUNTIFS($C$5:$C$120,$C27,$H$5:$H$120,">"&$H27) -> 4
A28: t6 | B28: Tree canopy lowers home cooling bills. | C28: trees | D28: 0 | E28: 0 | F28: 0 | G28: 0 | H28: =D28-E28+Settings!$B$3*(F28-G28) -> 0 | I28: =1+COUNTIFS($C$5:$C$120,$C28,$H$5:$H$120,">"&$H28) -> 4
A29: t7 | B29: Studies show a price premium for tree-lined streets. | C29: trees | D29: 0 | E29: 0 | F29: 0 | G29: 0 | H29: =D29-E29+Settings!$B$3*(F29-G29) -> 0 | I29: =1+COUNTIFS($C$5:$C$120,$C29,$H$5:$H$120,">"&$H29) -> 4
A30: t8 | B30: The premium disappears after controlling for neighborhood wealth. | C30: trees | D30: 0 | E30: 0 | F30: 0 | G30: 0 | H30: =D30-E30+Settings!$B$3*(F30-G30) -> 0 | I30: =1+COUNTIFS($C$5:$C$120,$C30,$H$5:$H$120,">"&$H30) -> 4
A31: t9 | B31: Root barriers and proper species choice prevent most damage. | C31: trees | D31: 0 | E31: 0 | F31: 0 | G31: 0 | H31: =D31-E31+Settings!$B$3*(F31-G31) -> 0 | I31: =1+COUNTIFS($C$5:$C$120,$C31,$H$5:$H$120,">"&$H31) -> 4

Sheet Edges
A1: Edges — one row per listed reason (the two columns on each workbook sheet)
A2: Blue cells are editable: linkage votes from the edge's sub-debate ('if this reason were true, would it really support that conclusion?'). LS = (agree - disagree) / (agree + disagree), or 1 when undebated. Contribution = child score x LS; the Nodes sheet multiplies it by m. To add a reason: insert a row INSIDE its parent's block of rows (so the parent's bounded ranges auto-expand), copy F/I/K down, and point J at the child's Nodes score cell.
A4: Edge | B4: Parent ID | C4: Parent conclusion | D4: Side | E4: Child ID | F4: Child statement | G4: Linkage agree votes | H4: Linkage disagree votes | I4: Linkage score (LS) | J4: Child score | K4: Contribution (child x LS)
A5: e46-47 | B5: 46 | C5: =IFERROR(INDEX(Nodes!$B$5:$B$120,MATCH($B5,Nodes!$A$5:$A$120,0)),"") -> Mormons should not be afraid of investigating the truth about their religion. | D5: agree | E5: 47 | F5: =IFERROR(INDEX(Nodes!$B$5:$B$120,MATCH($E5,Nodes!$A$5:$A$120,0)),"") -> Many LDS church leaders have encouraged the complete and utter loyalty to the Truth. | G5: 0 | H5: 0 | I5: =IF($G5+$H5=0,1,($G5-$H5)/($G5+$H5)) -> 1 | J5: =Nodes!$H$6 -> 5.57 | K5: =$J5*$I5 -> 5.57
A6: e46-48 | B6: 46 | C6: =IFERROR(INDEX(Nodes!$B$5:$B$120,MATCH($B6,Nodes!$A$5:$A$120,0)),"") -> Mormons should not be afraid of investigating the truth about their religion. | D6: agree | E6: 48 | F6: =IFERROR(INDEX(Nodes!$B$5:$B$120,MATCH($E6,Nodes!$A$5:$A$120,0)),"") -> LDS doctrine teaches that you cannot be saved in ignorance. | G6: 0 | H6: 0 | I6: =IF($G6+$H6=0,1,($G6-$H6)/($G6+$H6)) -> 1 | J6: =Nodes!$H$9 -> 2 | K6: =$J6*$I6 -> 2
A7: e46-296 | B7: 46 | C7: =IFERROR(INDEX(Nodes!$B$5:$B$120,MATCH($B7,Nodes!$A$5:$A$120,0)),"") -> Mormons should not be afraid of investigating the truth about their religion. | D7: agree | E7: 296 | F7: =IFERROR(INDEX(Nodes!$B$5:$B$120,MATCH($E7,Nodes!$A$5:$A$120,0)),"") -> If you cannot be saved in ignorance, you will eventually learn about all the Church's warts. | G7: 0 | H7: 0 | I7: =IF($G7+$H7=0,1,($G7-$H7)/($G7+$H7)) -> 1 | J7: =Nodes!$H$10 -> 1 | K7: =$J7*$I7 -> 1
A8: e46-297 | B8: 46 | C8: =IFERROR(INDEX(Nodes!$B$5:$B$120,MATCH($B8,Nodes!$A$5:$A$120,0)),"") -> Mormons should not be afraid of investigating the truth about their religion. | D8: agree | E8: 297 | F8: =IFERROR(INDEX(Nodes!$B$5:$B$120,MATCH($E8,Nodes!$A$5:$A$120,0)),"") -> Even if the Mormon Church is true, its leaders should not use half truths to keep people in it. | G8: 0 | H8: 0 | I8: =IF($G8+$H8=0,1,($G8-$H8)/($G8+$H8)) -> 1 | J8: =Nodes!$H$11 -> 1 | K8: =$J8*$I8 -> 1
A9: e47-45 | B9: 47 | C9: =IFERROR(INDEX(Nodes!$B$5:$B$120,MATCH($B9,Nodes!$A$5:$A$120,0)),"") -> Many LDS church leaders have encouraged the complete and utter loyalty to the Truth. | D9: agree | E9: 45 | F9: =IFERROR(INDEX(Nodes!$B$5:$B$120,MATCH($E9,Nodes!$A$5:$A$120,0)),"") -> President J. Reuben Clark was right: if we have the truth, it cannot be harmed by investigation. | G9: 0 | H9: 0 | I9: =IF($G9+$H9=0,1,($G9-$H9)/($G9+$H9)) -> 1 | J9: =Nodes!$H$7 -> 5.1 | K9: =$J9*$I9 -> 5.1
A10: e47-301 | B10: 47 | C10: =IFERROR(INDEX(Nodes!$B$5:$B$120,MATCH($B10,Nodes!$A$5:$A$120,0)),"") -> Many LDS church leaders have encouraged the complete and utter loyalty to the Truth. | D10: agree | E10: 301 | F10: =IFERROR(INDEX(Nodes!$B$5:$B$120,MATCH($E10,Nodes!$A$5:$A$120,0)),"") -> The whole narrative of Joseph Smith starting the Church is that he asked of God (James 1:5). | G10: 0 | H10: 0 | I10: =IF($G10+$H10=0,1,($G10-$H10)/($G10+$H10)) -> 1 | J10: =Nodes!$H$12 -> 0 | K10: =$J10*$I10 -> 0
A11: e48-302 | B11: 48 | C11: =IFERROR(INDEX(Nodes!$B$5:$B$120,MATCH($B11,Nodes!$A$5:$A$120,0)),"") -> LDS doctrine teaches that you cannot be saved in ignorance. | D11: agree | E11: 302 | F11: =IFERROR(INDEX(Nodes!$B$5:$B$120,MATCH($E11,Nodes!$A$5:$A$120,0)),"") -> D&C 131:6: It is impossible for a man to be saved in ignorance. | G11: 0 | H11: 0 | I11: =IF($G11+$H11=0,1,($G11-$H11)/($G11+$H11)) -> 1 | J11: =Nodes!$H$13 -> 0 | K11: =$J11*$I11 -> 0
A12: e48-303 | B12: 48 | C12: =IFERROR(INDEX(Nodes!$B$5:$B$120,MATCH($B12,Nodes!$A$5:$A$120,0)),"") -> LDS doctrine teaches that you cannot be saved in ignorance. | D12: agree | E12: 303 | F12: =IFERROR(INDEX(Nodes!$B$5:$B$120,MATCH($E12,Nodes!$A$5:$A$120,0)),"") -> D&C 137:7: All who have died without a knowledge of this gospel... shall be heirs. | G12: 0 | H12: 0 | I12: =IF($G12+$H12=0,1,($G12-$H12)/($G12+$H12)) -> 1 | J12: =Nodes!$H$14 -> 0 | K12: =$J12*$I12 -> 0
A13: e296-304 | B13: 296 | C13: =IFERROR(INDEX(Nodes!$B$5:$B$120,MATCH($B13,Nodes!$A$5:$A$120,0)),"") -> If you cannot be saved in ignorance, you will eventually learn about all the Church's warts. | D13: agree | E13: 304 | F13: =IFERROR(INDEX(Nodes!$B$5:$B$120,MATCH($E13,Nodes!$A$5:$A$120,0)),"") -> What information you expose yourself to determines what you learn eventually. | G13: 0 | H13: 0 | I13: =IF($G13+$H13=0,1,($G13-$H13)/($G13+$H13)) -> 1 | J13: =Nodes!$H$15 -> 0 | K13: =$J13*$I13 -> 0
A14: e297-305 | B14: 297 | C14: =IFERROR(INDEX(Nodes!$B$5:$B$120,MATCH($B14,Nodes!$A$5:$A$120,0)),"") -> Even if the Mormon Church is true, its leaders should not use half truths to keep people in it. | D14: agree | E14: 305 | F14: =IFERROR(INDEX(Nodes!$B$5:$B$120,MATCH($E14,Nodes!$A$5:$A$120,0)),"") -> Telling half truths or hiding the whole truth serves an agenda other than truth. | G14: 0 | H14: 0 | I14: =IF($G14+$H14=0,1,($G14-$H14)/($G14+$H14)) -> 1 | J14: =Nodes!$H$16 -> 0 | K14: =$J14*$I14 -> 0
A15: e45-30 | B15: 45 | C15: =IFERROR(INDEX(Nodes!$B$5:$B$120,MATCH($B15,Nodes!$A$5:$A$120,0)),"") -> President J. Reuben Clark was right: if we have the truth, it cannot be harmed by investigation. | D15: agree | E15: 30 | F15: =IFERROR(INDEX(Nodes!$B$5:$B$120,MATCH($E15,Nodes!$A$5:$A$120,0)),"") -> God is truth and knowledge; hiding truth to keep people in a religion is the opposite of God. | G15: 0 | H15: 0 | I15: =IF($G15+$H15=0,1,($G15-$H15)/($G15+$H15)) -> 1 | J15: =Nodes!$H$8 -> 1 | K15: =$J15*$I15 -> 1
A16: e45-48 | B16: 45 | C16: =IFERROR(INDEX(Nodes!$B$5:$B$120,MATCH($B16,Nodes!$A$5:$A$120,0)),"") -> President J. Reuben Clark was right: if we have the truth, it cannot be harmed by investigation. | D16: agree | E16: 48 | F16: =IFERROR(INDEX(Nodes!$B$5:$B$120,MATCH($E16,Nodes!$A$5:$A$120,0)),"") -> LDS doctrine teaches that you cannot be saved in ignorance. | G16: 0 | H16: 0 | I16: =IF($G16+$H16=0,1,($G16-$H16)/($G16+$H16)) -> 1 | J16: =Nodes!$H$9 -> 2 | K16: =$J16*$I16 -> 2
A17: e45-306 | B17: 45 | C17: =IFERROR(INDEX(Nodes!$B$5:$B$120,MATCH($B17,Nodes!$A$5:$A$120,0)),"") -> President J. Reuben Clark was right: if we have the truth, it cannot be harmed by investigation. | D17: agree | E17: 306 | F17: =IFERROR(INDEX(Nodes!$B$5:$B$120,MATCH($E17,Nodes!$A$5:$A$120,0)),"") -> Truth is always helped by honest, logical, transparent investigation. | G17: 0 | H17: 0 | I17: =IF($G17+$H17=0,1,($G17-$H17)/($G17+$H17)) -> 1 | J17: =Nodes!$H$17 -> 0 | K17: =$J17*$I17 -> 0
A18: e45-307 | B18: 45 | C18: =IFERROR(INDEX(Nodes!$B$5:$B$120,MATCH($B18,Nodes!$A$5:$A$120,0)),"") -> President J. Reuben Clark was right: if we have the truth, it cannot be harmed by investigation. | D18: agree | E18: 307 | F18: =IFERROR(INDEX(Nodes!$B$5:$B$120,MATCH($E18,Nodes!$A$5:$A$120,0)),"") -> Even if the Mormon Church is true, they shouldn't lie to keep people in it. | G18: 0 | H18: 0 | I18: =IF($G18+$H18=0,1,($G18-$H18)/($G18+$H18)) -> 1 | J18: =Nodes!$H$18 -> 0 | K18: =$J18*$I18 -> 0
A19: e45-308 | B19: 45 | C19: =IFERROR(INDEX(Nodes!$B$5:$B$120,MATCH($B19,Nodes!$A$5:$A$120,0)),"") -> President J. Reuben Clark was right: if we have the truth, it cannot be harmed by investigation. | D19: disagree | E19: 308 | F19: =IFERROR(INDEX(Nodes!$B$5:$B$120,MATCH($E19,Nodes!$A$5:$A$120,0)),"") -> If God wants everyone to be Mormon, it is more important to tell faith-promoting stories. | G19: 0 | H19: 0 | I19: =IF($G19+$H19=0,1,($G19-$H19)/($G19+$H19)) -> 1 | J19: =Nodes!$H$19 -> 0 | K19: =$J19*$I19 -> 0
A20: e30-309 | B20: 30 | C20: =IFERROR(INDEX(Nodes!$B$5:$B$120,MATCH($B20,Nodes!$A$5:$A$120,0)),"") -> God is truth and knowledge; hiding truth to keep people in a religion is the opposite of God. | D20: agree | E20: 309 | F20: =IFERROR(INDEX(Nodes!$B$5:$B$120,MATCH($E20,Nodes!$A$5:$A$120,0)),"") -> The 10 commandments tell us not to bear false witness. | G20: 0 | H20: 0 | I20: =IF($G20+$H20=0,1,($G20-$H20)/($G20+$H20)) -> 1 | J20: =Nodes!$H$20 -> 0 | K20: =$J20*$I20 -> 0
A21: e30-310 | B21: 30 | C21: =IFERROR(INDEX(Nodes!$B$5:$B$120,MATCH($B21,Nodes!$A$5:$A$120,0)),"") -> God is truth and knowledge; hiding truth to keep people in a religion is the opposite of God. | D21: agree | E21: 310 | F21: =IFERROR(INDEX(Nodes!$B$5:$B$120,MATCH($E21,Nodes!$A$5:$A$120,0)),"") -> Mormons are told not to lie, or do anything like unto it. | G21: 0 | H21: 0 | I21: =IF($G21+$H21=0,1,($G21-$H21)/($G21+$H21)) -> 1 | J21: =Nodes!$H$21 -> 0 | K21: =$J21*$I21 -> 0
A22: e30-311 | B22: 30 | C22: =IFERROR(INDEX(Nodes!$B$5:$B$120,MATCH($B22,Nodes!$A$5:$A$120,0)),"") -> God is truth and knowledge; hiding truth to keep people in a religion is the opposite of God. | D22: disagree | E22: 311 | F22: =IFERROR(INDEX(Nodes!$B$5:$B$120,MATCH($E22,Nodes!$A$5:$A$120,0)),"") -> Jesus said people should be given milk before meat. | G22: 0 | H22: 0 | I22: =IF($G22+$H22=0,1,($G22-$H22)/($G22+$H22)) -> 1 | J22: =Nodes!$H$22 -> 0 | K22: =$J22*$I22 -> 0
A23: et1-t2 | B23: t1 | C23: =IFERROR(INDEX(Nodes!$B$5:$B$120,MATCH($B23,Nodes!$A$5:$A$120,0)),"") -> Our city should plant more street trees. | D23: agree | E23: t2 | F23: =IFERROR(INDEX(Nodes!$B$5:$B$120,MATCH($E23,Nodes!$A$5:$A$120,0)),"") -> Street trees measurably cool neighborhoods in summer. | G23: 4 | H23: 0 | I23: =IF($G23+$H23=0,1,($G23-$H23)/($G23+$H23)) -> 1 | J23: =Nodes!$H$24 -> 2 | K23: =$J23*$I23 -> 2
A24: et1-t3 | B24: t1 | C24: =IFERROR(INDEX(Nodes!$B$5:$B$120,MATCH($B24,Nodes!$A$5:$A$120,0)),"") -> Our city should plant more street trees. | D24: agree | E24: t3 | F24: =IFERROR(INDEX(Nodes!$B$5:$B$120,MATCH($E24,Nodes!$A$5:$A$120,0)),"") -> Street trees increase nearby property values. | G24: 3 | H24: 1 | I24: =IF($G24+$H24=0,1,($G24-$H24)/($G24+$H24)) -> 0.5 | J24: =Nodes!$H$25 -> 0 | K24: =$J24*$I24 -> 0
A25: et1-t4 | B25: t1 | C25: =IFERROR(INDEX(Nodes!$B$5:$B$120,MATCH($B25,Nodes!$A$5:$A$120,0)),"") -> Our city should plant more street trees. | D25: disagree | E25: t4 | F25: =IFERROR(INDEX(Nodes!$B$5:$B$120,MATCH($E25,Nodes!$A$5:$A$120,0)),"") -> Tree roots damage sidewalks and raise repair costs. | G25: 3 | H25: 1 | I25: =IF($G25+$H25=0,1,($G25-$H25)/($G25+$H25)) -> 0.5 | J25: =Nodes!$H$26 -> 1 | K25: =$J25*$I25 -> 0.5
A26: et2-t5 | B26: t2 | C26: =IFERROR(INDEX(Nodes!$B$5:$B$120,MATCH($B26,Nodes!$A$5:$A$120,0)),"") -> Street trees measurably cool neighborhoods in summer. | D26: agree | E26: t5 | F26: =IFERROR(INDEX(Nodes!$B$5:$B$120,MATCH($E26,Nodes!$A$5:$A$120,0)),"") -> Shaded pavement stays 10-15 degrees cooler in heat waves. | G26: 0 | H26: 0 | I26: =IF($G26+$H26=0,1,($G26-$H26)/($G26+$H26)) -> 1 | J26: =Nodes!$H$27 -> 0 | K26: =$J26*$I26 -> 0
A27: et2-t6 | B27: t2 | C27: =IFERROR(INDEX(Nodes!$B$5:$B$120,MATCH($B27,Nodes!$A$5:$A$120,0)),"") -> Street trees measurably cool neighborhoods in summer. | D27: agree | E27: t6 | F27: =IFERROR(INDEX(Nodes!$B$5:$B$120,MATCH($E27,Nodes!$A$5:$A$120,0)),"") -> Tree canopy lowers home cooling bills. | G27: 0 | H27: 0 | I27: =IF($G27+$H27=0,1,($G27-$H27)/($G27+$H27)) -> 1 | J27: =Nodes!$H$28 -> 0 | K27: =$J27*$I27 -> 0
A28: et3-t7 | B28: t3 | C28: =IFERROR(INDEX(Nodes!$B$5:$B$120,MATCH($B28,Nodes!$A$5:$A$120,0)),"") -> Street trees increase nearby property values. | D28: agree | E28: t7 | F28: =IFERROR(INDEX(Nodes!$B$5:$B$120,MATCH($E28,Nodes!$A$5:$A$120,0)),"") -> Studies show a price premium for tree-lined streets. | G28: 0 | H28: 0 | I28: =IF($G28+$H28=0,1,($G28-$H28)/($G28+$H28)) -> 1 | J28: =Nodes!$H$29 -> 0 | K28: =$J28*$I28 -> 0
A29: et3-t8 | B29: t3 | C29: =IFERROR(INDEX(Nodes!$B$5:$B$120,MATCH($B29,Nodes!$A$5:$A$120,0)),"") -> Street trees increase nearby property values. | D29: disagree | E29: t8 | F29: =IFERROR(INDEX(Nodes!$B$5:$B$120,MATCH($E29,Nodes!$A$5:$A$120,0)),"") -> The premium disappears after controlling for neighborhood wealth. | G29: 0 | H29: 0 | I29: =IF($G29+$H29=0,1,($G29-$H29)/($G29+$H29)) -> 1 | J29: =Nodes!$H$30 -> 0 | K29: =$J29*$I29 -> 0
A30: et4-t9 | B30: t4 | C30: =IFERROR(INDEX(Nodes!$B$5:$B$120,MATCH($B30,Nodes!$A$5:$A$120,0)),"") -> Tree roots damage sidewalks and raise repair costs. | D30: agree | E30: t9 | F30: =IFERROR(INDEX(Nodes!$B$5:$B$120,MATCH($E30,Nodes!$A$5:$A$120,0)),"") -> Root barriers and proper species choice prevent most damage. | G30: 0 | H30: 0 | I30: =IF($G30+$H30=0,1,($G30-$H30)/($G30+$H30)) -> 1 | J30: =Nodes!$H$31 -> 0 | K30: =$J30*$I30 -> 0

Sheet Scoreboard
A1: Scoreboard — every conclusion, ranked (the workbook's Index sheet)
A2: All values are live lookups into Nodes. Rows are printed in the default (m = 0.7) order; if you change inputs, the Rank column re-ranks even though rows stay put.
A4: From the original workbook (belief 46 and its sub-arguments)
A5: Rank | B5: ID | C5: Conclusion | D5: # agree | E5: # disagree | F5: Score
A6: =Nodes!$I$5 -> 1 | B6: 46 | C6: =Nodes!$B$5 -> Mormons should not be afraid of investigating the truth about their religion. | D6: =Nodes!$D$5 -> 4 | E6: =Nodes!$E$5 -> 0 | F6: =Nodes!$H$5 -> 10.699
A7: =Nodes!$I$6 -> 2 | B7: 47 | C7: =Nodes!$B$6 -> Many LDS church leaders have encouraged the complete and utter loyalty to the Truth. | D7: =Nodes!$D$6 -> 2 | E7: =Nodes!$E$6 -> 0 | F7: =Nodes!$H$6 -> 5.57
A8: =Nodes!$I$7 -> 3 | B8: 45 | C8: =Nodes!$B$7 -> President J. Reuben Clark was right: if we have the truth, it cannot be harmed by investigation. | D8: =Nodes!$D$7 -> 4 | E8: =Nodes!$E$7 -> 1 | F8: =Nodes!$H$7 -> 5.1
A9: =Nodes!$I$9 -> 4 | B9: 48 | C9: =Nodes!$B$9 -> LDS doctrine teaches that you cannot be saved in ignorance. | D9: =Nodes!$D$9 -> 2 | E9: =Nodes!$E$9 -> 0 | F9: =Nodes!$H$9 -> 2
A10: =Nodes!$I$8 -> 5 | B10: 30 | C10: =Nodes!$B$8 -> God is truth and knowledge; hiding truth to keep people in a religion is the opposite of God. | D10: =Nodes!$D$8 -> 2 | E10: =Nodes!$E$8 -> 1 | F10: =Nodes!$H$8 -> 1
A11: =Nodes!$I$10 -> 5 | B11: 296 | C11: =Nodes!$B$10 -> If you cannot be saved in ignorance, you will eventually learn about all the Church's warts. | D11: =Nodes!$D$10 -> 1 | E11: =Nodes!$E$10 -> 0 | F11: =Nodes!$H$10 -> 1
A12: =Nodes!$I$11 -> 5 | B12: 297 | C12: =Nodes!$B$11 -> Even if the Mormon Church is true, its leaders should not use half truths to keep people in it. | D12: =Nodes!$D$11 -> 1 | E12: =Nodes!$E$11 -> 0 | F12: =Nodes!$H$11 -> 1
A13: =Nodes!$I$12 -> 8 | B13: 301 | C13: =Nodes!$B$12 -> The whole narrative of Joseph Smith starting the Church is that he asked of God (James 1:5). | D13: =Nodes!$D$12 -> 0 | E13: =Nodes!$E$12 -> 0 | F13: =Nodes!$H$12 -> 0
A14: =Nodes!$I$13 -> 8 | B14: 302 | C14: =Nodes!$B$13 -> D&C 131:6: It is impossible for a man to be saved in ignorance. | D14: =Nodes!$D$13 -> 0 | E14: =Nodes!$E$13 -> 0 | F14: =Nodes!$H$13 -> 0
A15: =Nodes!$I$14 -> 8 | B15: 303 | C15: =Nodes!$B$14 -> D&C 137:7: All who have died without a knowledge of this gospel... shall be heirs. | D15: =Nodes!$D$14 -> 0 | E15: =Nodes!$E$14 -> 0 | F15: =Nodes!$H$14 -> 0
A16: =Nodes!$I$15 -> 8 | B16: 304 | C16: =Nodes!$B$15 -> What information you expose yourself to determines what you learn eventually. | D16: =Nodes!$D$15 -> 0 | E16: =Nodes!$E$15 -> 0 | F16: =Nodes!$H$15 -> 0
A17: =Nodes!$I$16 -> 8 | B17: 305 | C17: =Nodes!$B$16 -> Telling half truths or hiding the whole truth serves an agenda other than truth. | D17: =Nodes!$D$16 -> 0 | E17: =Nodes!$E$16 -> 0 | F17: =Nodes!$H$16 -> 0
A18: =Nodes!$I$17 -> 8 | B18: 306 | C18: =Nodes!$B$17 -> Truth is always helped by honest, logical, transparent investigation. | D18: =Nodes!$D$17 -> 0 | E18: =Nodes!$E$17 -> 0 | F18: =Nodes!$H$17 -> 0
A19: =Nodes!$I$18 -> 8 | B19: 307 | C19: =Nodes!$B$18 -> Even if the Mormon Church is true, they shouldn't lie to keep people in it. | D19: =Nodes!$D$18 -> 0 | E19: =Nodes!$E$18 -> 0 | F19: =Nodes!$H$18 -> 0
A20: =Nodes!$I$19 -> 8 | B20: 308 | C20: =Nodes!$B$19 -> If God wants everyone to be Mormon, it is more important to tell faith-promoting stories. | D20: =Nodes!$D$19 -> 0 | E20: =Nodes!$E$19 -> 0 | F20: =Nodes!$H$19 -> 0
A21: =Nodes!$I$20 -> 8 | B21: 309 | C21: =Nodes!$B$20 -> The 10 commandments tell us not to bear false witness. | D21: =Nodes!$D$20 -> 0 | E21: =Nodes!$E$20 -> 0 | F21: =Nodes!$H$20 -> 0
A22: =Nodes!$I$21 -> 8 | B22: 310 | C22: =Nodes!$B$21 -> Mormons are told not to lie, or do anything like unto it. | D22: =Nodes!$D$21 -> 0 | E22: =Nodes!$E$21 -> 0 | F22: =Nodes!$H$21 -> 0
A23: =Nodes!$I$22 -> 8 | B23: 311 | C23: =Nodes!$B$22 -> Jesus said people should be given milk before meat. | D23: =Nodes!$D$22 -> 0 | E23: =Nodes!$E$22 -> 0 | F23: =Nodes!$H$22 -> 0
A26: Synthetic street-trees example (exercises linkage scores)
A27: Rank | B27: ID | C27: Conclusion | D27: # agree | E27: # disagree | F27: Score
A28: =Nodes!$I$23 -> 1 | B28: t1 | C28: =Nodes!$B$23 -> Our city should plant more street trees. | D28: =Nodes!$D$23 -> 2 | E28: =Nodes!$E$23 -> 1 | F28: =Nodes!$H$23 -> 2.05
A29: =Nodes!$I$24 -> 2 | B29: t2 | C29: =Nodes!$B$24 -> Street trees measurably cool neighborhoods in summer. | D29: =Nodes!$D$24 -> 2 | E29: =Nodes!$E$24 -> 0 | F29: =Nodes!$H$24 -> 2
A30: =Nodes!$I$26 -> 3 | B30: t4 | C30: =Nodes!$B$26 -> Tree roots damage sidewalks and raise repair costs. | D30: =Nodes!$D$26 -> 1 | E30: =Nodes!$E$26 -> 0 | F30: =Nodes!$H$26 -> 1
A31: =Nodes!$I$25 -> 4 | B31: t3 | C31: =Nodes!$B$25 -> Street trees increase nearby property values. | D31: =Nodes!$D$25 -> 1 | E31: =Nodes!$E$25 -> 1 | F31: =Nodes!$H$25 -> 0
A32: =Nodes!$I$27 -> 4 | B32: t5 | C32: =Nodes!$B$27 -> Shaded pavement stays 10-15 degrees cooler in heat waves. | D32: =Nodes!$D$27 -> 0 | E32: =Nodes!$E$27 -> 0 | F32: =Nodes!$H$27 -> 0
A33: =Nodes!$I$28 -> 4 | B33: t6 | C33: =Nodes!$B$28 -> Tree canopy lowers home cooling bills. | D33: =Nodes!$D$28 -> 0 | E33: =Nodes!$E$28 -> 0 | F33: =Nodes!$H$28 -> 0
A34: =Nodes!$I$29 -> 4 | B34: t7 | C34: =Nodes!$B$29 -> Studies show a price premium for tree-lined streets. | D34: =Nodes!$D$29 -> 0 | E34: =Nodes!$E$29 -> 0 | F34: =Nodes!$H$29 -> 0
A35: =Nodes!$I$30 -> 4 | B35: t8 | C35: =Nodes!$B$30 -> The premium disappears after controlling for neighborhood wealth. | D35: =Nodes!$D$30 -> 0 | E35: =Nodes!$E$30 -> 0 | F35: =Nodes!$H$30 -> 0
A36: =Nodes!$I$31 -> 4 | B36: t9 | C36: =Nodes!$B$31 -> Root barriers and proper species choice prevent most damage. | D36: =Nodes!$D$31 -> 0 | E36: =Nodes!$E$31 -> 0 | F36: =Nodes!$H$31 -> 0

Sheet Walkthrough
A1: How one score is computed, step by step
A2: Column C shows the formula in words; column D computes it live. Change Settings!B3 or any blue cell on Edges and watch every step move.
A4: Conclusion t1: Our city should plant more street trees.
A6: Step | B6: What | C6: How | D6: Value
A7: 1 | B7: Count the reasons to agree | C7: COUNTIFS on Edges, side = agree | D7: =Nodes!$D$23 -> 2
A8: 2 | B8: Count the reasons to disagree | C8: COUNTIFS on Edges, side = disagree | D8: =Nodes!$E$23 -> 1
A9: 3 | B9: Raw score | C9: step 1 - step 2 (one point per listed reason) | D9: =Nodes!$D$23-Nodes!$E$23 -> 1
A10: 4 | B10: Each reason's own score, weighted by its linkage | C10: rows pulled live from the Edges sheet
B11: Reason (child) | C11: Side | D11: Own score | E11: LS | F11: Child x LS
B12: =Edges!$F$23 -> Street trees measurably cool neighborhoods in summer. | C12: =Edges!$D$23 -> agree | D12: =Edges!$J$23 -> 2 | E12: =Edges!$I$23 -> 1 | F12: =Edges!$K$23 -> 2
B13: =Edges!$F$24 -> Street trees increase nearby property values. | C13: =Edges!$D$24 -> agree | D13: =Edges!$J$24 -> 0 | E13: =Edges!$I$24 -> 0.5 | F13: =Edges!$K$24 -> 0
B14: =Edges!$F$25 -> Tree roots damage sidewalks and raise repair costs. | C14: =Edges!$D$25 -> disagree | D14: =Edges!$J$25 -> 1 | E14: =Edges!$I$25 -> 0.5 | F14: =Edges!$K$25 -> 0.5
A15: 5 | B15: Sum of agree contributions | C15: SUMIFS over the rows above (agree side) | D15: =Nodes!$F$23 -> 2
A16: 6 | B16: Sum of disagree contributions | C16: SUMIFS over the rows above (disagree side) | D16: =Nodes!$G$23 -> 0.5
A17: 7 | B17: The sub-argument multiplier m | C17: Settings!B3 (the workbook's Index!O1) | D17: =Settings!$B$3 -> 0.7
A18: 8 | B18: Final score | C18: step 3 + m x (step 5 - step 6) | D18: =Nodes!$D$23-Nodes!$E$23+Settings!$B$3*(Nodes!$F$23-Nodes!$G$23) -> 2.05
B19: Check: equals the Nodes-sheet score for this row? | D19: =IF(ABS(D18-Nodes!$H$23)<0.0000001,"YES","NO") -> YES
A22: Conclusion 46: Mormons should not be afraid of investigating the truth about their religion.
A24: Step | B24: What | C24: How | D24: Value
A25: 1 | B25: Count the reasons to agree | C25: COUNTIFS on Edges, side = agree | D25: =Nodes!$D$5 -> 4
A26: 2 | B26: Count the reasons to disagree | C26: COUNTIFS on Edges, side = disagree | D26: =Nodes!$E$5 -> 0
A27: 3 | B27: Raw score | C27: step 1 - step 2 (one point per listed reason) | D27: =Nodes!$D$5-Nodes!$E$5 -> 4
A28: 4 | B28: Each reason's own score, weighted by its linkage | C28: rows pulled live from the Edges sheet
B29: Reason (child) | C29: Side | D29: Own score | E29: LS | F29: Child x LS
B30: =Edges!$F$5 -> Many LDS church leaders have encouraged the complete and utter loyalty to the Truth. | C30: =Edges!$D$5 -> agree | D30: =Edges!$J$5 -> 5.57 | E30: =Edges!$I$5 -> 1 | F30: =Edges!$K$5 -> 5.57
B31: =Edges!$F$6 -> LDS doctrine teaches that you cannot be saved in ignorance. | C31: =Edges!$D$6 -> agree | D31: =Edges!$J$6 -> 2 | E31: =Edges!$I$6 -> 1 | F31: =Edges!$K$6 -> 2
B32: =Edges!$F$7 -> If you cannot be saved in ignorance, you will eventually learn about all the Church's warts. | C32: =Edges!$D$7 -> agree | D32: =Edges!$J$7 -> 1 | E32: =Edges!$I$7 -> 1 | F32: =Edges!$K$7 -> 1
B33: =Edges!$F$8 -> Even if the Mormon Church is true, its leaders should not use half truths to keep people in it. | C33: =Edges!$D$8 -> agree | D33: =Edges!$J$8 -> 1 | E33: =Edges!$I$8 -> 1 | F33: =Edges!$K$8 -> 1
A34: 5 | B34: Sum of agree contributions | C34: SUMIFS over the rows above (agree side) | D34: =Nodes!$F$5 -> 9.57
A35: 6 | B35: Sum of disagree contributions | C35: SUMIFS over the rows above (disagree side) | D35: =Nodes!$G$5 -> 0
A36: 7 | B36: The sub-argument multiplier m | C36: Settings!B3 (the workbook's Index!O1) | D36: =Settings!$B$3 -> 0.7
A37: 8 | B37: Final score | C37: step 3 + m x (step 5 - step 6) | D37: =Nodes!$D$5-Nodes!$E$5+Settings!$B$3*(Nodes!$F$5-Nodes!$G$5) -> 10.699
B38: Check: equals the Nodes-sheet score for this row? | D38: =IF(ABS(D37-Nodes!$H$5)<0.0000001,"YES","NO") -> YES
A41: Linkage score mini-calculator
A42: An edge's linkage score comes from its own little debate: 'if this reason were true, would it actually support that conclusion?' Type any vote counts:
A44: Votes agree | B44: Votes disagree | C44: Linkage score
A45: 4 | B45: 0 | C45: =IF(A45+B45=0,1,(A45-B45)/(A45+B45)) -> 1
A46: 3 | B46: 1 | C46: =IF(A46+B46=0,1,(A46-B46)/(A46+B46)) -> 0.5
A47: 2 | B47: 2 | C47: =IF(A47+B47=0,1,(A47-B47)/(A47+B47)) -> 0
A48: 1 | B48: 3 | C48: =IF(A48+B48=0,1,(A48-B48)/(A48+B48)) -> -0.5
...
